<?xml version="1.0"?>
<robot name="travis_bot" xmlns:xacro="http://ros.org/wiki/xacro">

    <xacro:property name="base_width" value="1"/>
    <xacro:property name="base_length" value="1"/>
    <xacro:property name="base_height" value="0.5"/>

    <xacro:property name="wheel_radius" value="0.5"/>
    <xacro:property name="wheel_width" value="0.1"/>

    <xacro:property name="wheel_xoff" value="0.25"/>
    <xacro:property name="wheel_ygap" value="0.1"/>
    <xacro:property name="wheel_zoff" value="0.25"/>
    

    <link name="base_link">
        <visual>
        <geometry>
            <box size="${base_length} ${base_width} ${base_height}"/>
        </geometry>
        <material name="Cyan">
            <color rgba="0 1.0 1.0 1.0"/>
        </material>
        </visual>
    </link>

    <link name="base_footprint"/>

    <joint name="base_joint">
        <parent link="base_footprint"/>
        <child link="base_link"/>
        <origin xyz="0.0 0.0 0.0" rpy="0 0 0"/> 
    </joint>

    <xacro:macro name="wheel" params="prefix x_reflect y_reflect">
    <link name="${prefix}_link">
      <visual>
        <origin xyz="0 0 0" rpy="${pi/2} 0 0"/>
        <geometry>
            <cylinder radius="${wheel_radius}" length="${wheel_width}"/>
        </geometry>
        <material name="Gray">
          <color rgba="0.5 0.5 0.5 1.0"/>
        </material>
      </visual>
    </link>

    <joint name="${prefix}_joint" type="continuous">
      <parent link="base_link"/>
      <child link="${prefix}_link"/>
      <origin xyz="${x_reflect*wheel_xoff} ${y_reflect*(base_width/2+wheel_ygap)} ${-wheel_zoff}" rpy="0 0 0"/>
      <axis xyz="0 1 0"/>
    </joint>
  </xacro:macro>

  <xacro:wheel prefix="drivewhl_l" x_reflect="-1" y_reflect="1" />
  <xacro:wheel prefix="drivewhl_r" x_reflect="-1" y_reflect="-1" />
        

</robot>